Workbook

Sheet Tablero
B2: FASE 0 — CIMENTAR · BACKLOG OPERATIVO
B3: Horizonte 0–6 meses · planteamiento dual (Track A interno + Track B wedge) sobre la espina dorsal de industrialización
B5: INDICADORES
B6: Tareas totales | C6: Esfuerzo total (sem) | D6: % completado | F6: Tareas P0 (críticas) | G6: Bloqueadas
B7: =COUNTA(Backlog!A2:A32) | C7: =SUM(Backlog!H2:H32) | D7: =IF(B7=0,0,COUNTIF(Backlog!J2:J32,"Hecho")/B7) | F7: =COUNTIF(Backlog!G2:G32,"P0") | G7: =COUNTIF(Backlog!J2:J32,"Bloqueado")
B10: POR ESTADO | F10: CRITERIO DE SALIDA (GATE PARA INICIAR LA FASE 1)
B11: Estado | C11: Nº | F11: Hito del gate | G11: Épica | H11: Estado
B12: Pendiente | C12: =COUNTIF(Backlog!J2:J32,"Pendiente") | F12: Suite de casos golden cubriendo módulos críticos y en verde | G12: N2 | H12: Pendiente
B13: En curso | C13: =COUNTIF(Backlog!J2:J32,"En curso") | F13: Baseline de ROI interno documentado | G13: A2 | H13: Pendiente
B14: Bloqueado | C14: =COUNTIF(Backlog!J2:J32,"Bloqueado") | F14: PRD del wedge aprobado | G14: B1 | H14: Pendiente
B15: Hecho | C15: =COUNTIF(Backlog!J2:J32,"Hecho") | F15: ≥3 cartas de intención (LOI) firmadas | G15: B3 | H15: Pendiente
B18: POR TRACK | F18: NOTA
B19: Track | C19: Nº | D19: Sem | F19: Roles orientativos (rellena nombres reales en la hoja Roles). Estimaciones en semanas-persona. Las celdas con lista despegable están en Backlog (Track, Responsable, Prioridad, Mes, Estado).
B20: A · Interno | C20: =COUNTIF(Backlog!B2:B32,"A · Interno") | D20: =SUMIF(Backlog!B2:B32,"A · Interno",Backlog!H2:H32)
B21: B · Wedge | C21: =COUNTIF(Backlog!B2:B32,"B · Wedge") | D21: =SUMIF(Backlog!B2:B32,"B · Wedge",Backlog!H2:H32)
B22: N · Núcleo/Industrialización | C22: =COUNTIF(Backlog!B2:B32,"N · Núcleo/Industrialización") | D22: =SUMIF(Backlog!B2:B32,"N · Núcleo/Industrialización",Backlog!H2:H32)

Sheet Gantt
A1: DIAGRAMA DE GANTT — FASE 0 · CIMENTAR
A2: Horizonte 0–6 meses · barras según mes objetivo y esfuerzo estimado · ◆ = entregable de fase
A4: ID | B4: Tarea | C4: Responsable | D4: Pri. | E4: M1 | F4: M2 | G4: M3 | H4: M4 | I4: M5 | J4: M6
A5: TRACK A · USO INTERNO
A6: A1.1 | B6: Seleccionar 2-3 proyectos propios representativos | C6: Dirección (JM) | D6: P0
A7: A2.1 | B7: Definir métricas (horas/entregable, tasa de retrabajo) | C7: Producto (PM) | D7: P0
A8: A2.2 | B8: Instrumentar el registro de tiempos | C8: Producto (PM) | D8: P1
A9: A1.2 | B9: Ejecutar cada proyecto end-to-end con el ecosistema | C9: Ing. Núcleo / FEM | D9: P0
A10: A1.3 | B10: Registrar incidencias, fricciones y tiempos | C10: QA / Verificación | D10: P1
A11: A1.4 | B11: Documentar criterios de despacho en la memoria | C11: Dirección (JM) | D11: P1
A12: A2.3 | B12: Recoger datos en los proyectos piloto | C12: QA / Verificación | D12: P1
A13: A2.4 | B13: Redactar la Memoria de baseline de ROI | C13: Dirección (JM) | D13: P0 | H13: ◆
A14: TRACK B · WEDGE BIM/CUMPLIMIENTO
A15: B1.1 | B15: Delimitar el alcance funcional (Visor + ISO 19650 + CTE) | C15: Producto (PM) | D15: P0
A16: B1.2 | B16: Definir la frontera con el cálculo (qué queda fuera) | C16: Producto (PM) | D16: P0
A17: B1.3 | B17: Definir buyer persona y propuesta de valor | C17: Negocio / Comercial | D17: P1
A18: B1.4 | B18: Pricing preliminar y modelo de suscripción | C18: Negocio / Comercial | D18: P1
A19: B2.1 | B19: Inventariar componentes existentes y su madurez | C19: Ing. BIM / IFC | D19: P0
A20: B3.1 | B20: Identificar 3-5 despachos candidatos | C20: Negocio / Comercial | D20: P0
A21: B1.5 | B21: Redactar y aprobar el PRD | C21: Producto (PM) | D21: P0 | G21: ◆
A22: B2.2 | B22: Identificar gaps funcionales del MVP | C22: Ing. BIM / IFC | D22: P1
A23: B3.2 | B23: Preparar material de pitch / demo | C23: Negocio / Comercial | D23: P1
A24: B2.3 | B24: Plan de empaquetado como aplicación web | C24: Ing. BIM / IFC | D24: P1
A25: B3.3 | B25: Contactar y cualificar candidatos | C25: Negocio / Comercial | D25: P1
A26: B3.4 | B26: Firmar cartas de intención (LOI) | C26: Dirección (JM) | D26: P0 | I26: ◆
A27: TRACK N · NÚCLEO / INDUSTRIALIZACIÓN
A28: N1.1 | B28: Consolidar monorepo y control de versiones | C28: Ing. Núcleo / FEM | D28: P0
A29: N3.1 | B29: Definir KPIs de la fase y umbrales del gate | C29: Dirección (JM) | D29: P1
A30: N3.2 | B30: Tablero de seguimiento del backlog | C30: Producto (PM) | D30: P1
A31: N1.2 | B31: Fijar dependencias y build determinista | C31: Ing. Núcleo / FEM | D31: P0
A32: N1.3 | B32: Empaquetado firmado de núcleo y plugins | C32: Ing. Núcleo / FEM | D32: P1
A33: N2.2 | B33: Definir el oráculo numérico de referencia | C33: Ing. Núcleo / FEM | D33: P0
A34: N1.4 | B34: Documentar la toolchain | C34: Ing. Núcleo / FEM | D34: P2
A35: N2.1 | B35: Formalizar casos existentes (PUE/LIN/INC) como suite | C35: QA / Verificación | D35: P0
A36: N2.3 | B36: Automatizar las puertas espejo/APTO | C36: QA / Verificación | D36: P0
A37: N3.3 | B37: Instrumentación básica de coste de inferencia | C37: Ing. Núcleo / FEM | D37: P2
A38: N2.4 | B38: Informe de validación numérica (baseline) | C38: QA / Verificación | D38: P0 | I38: ◆
A40: LEYENDA
B41: Track A · uso interno
B42: Track B · wedge
...

Sheet Backlog
A1: ID | B1: Track | C1: Épica | D1: Tarea | E1: Entregable / Definición de hecho | F1: Responsable (rol) | G1: Prioridad | H1: Estim. (sem) | I1: Mes obj. | J1: Estado | K1: Avance % | L1: Depende de
A2: A1.1 | B2: A · Interno | C2: A1 · Operación en proyectos piloto internos | D2: Seleccionar 2-3 proyectos propios representativos | E2: Lista de proyectos con alcance y disciplinas implicadas | F2: Dirección (JM) | G2: P0 | H2: 1 | I2: M1 | J2: Pendiente | K2: 0
A3: A1.2 | B3: A · Interno | C3: A1 · Operación en proyectos piloto internos | D3: Ejecutar cada proyecto end-to-end con el ecosistema | E3: Proyectos calculados/documentados con los agentes | F3: Ing. Núcleo / FEM | G3: P0 | H3: 8 | I3: M2 | J3: Pendiente | K3: 0 | L3: A1.1
A4: A1.3 | B4: A · Interno | C4: A1 · Operación en proyectos piloto internos | D4: Registrar incidencias, fricciones y tiempos | E4: Registro de incidencias y log de tiempos por tarea | F4: QA / Verificación | G4: P1 | H4: 4 | I4: M2 | J4: Pendiente | K4: 0 | L4: A1.2
A5: A1.4 | B5: A · Interno | C5: A1 · Operación en proyectos piloto internos | D5: Documentar criterios de despacho en la memoria | E5: Memoria de criterios de despacho actualizada | F5: Dirección (JM) | G5: P1 | H5: 3 | I5: M3 | J5: Pendiente | K5: 0 | L5: A1.2
A6: A2.1 | B6: A · Interno | C6: A2 · Baseline de ROI interno | D6: Definir métricas (horas/entregable, tasa de retrabajo) | E6: Cuadro de métricas y método de medición | F6: Producto (PM) | G6: P0 | H6: 1 | I6: M1 | J6: Pendiente | K6: 0
A7: A2.2 | B7: A · Interno | C7: A2 · Baseline de ROI interno | D7: Instrumentar el registro de tiempos | E7: Plantilla/herramienta de registro operativa | F7: Producto (PM) | G7: P1 | H7: 2 | I7: M1 | J7: Pendiente | K7: 0 | L7: A2.1
A8: A2.3 | B8: A · Interno | C8: A2 · Baseline de ROI interno | D8: Recoger datos en los proyectos piloto | E8: Dataset de horas y retrabajo por entregable | F8: QA / Verificación | G8: P1 | H8: 4 | I8: M3 | J8: Pendiente | K8: 0 | L8: A2.2;A1.2
A9: A2.4 | B9: A · Interno | C9: A2 · Baseline de ROI interno | D9: Redactar la Memoria de baseline de ROI | E9: Memoria de baseline de ROI (ENTREGABLE DE FASE) | F9: Dirección (JM) | G9: P0 | H9: 2 | I9: M4 | J9: Pendiente | K9: 0 | L9: A2.3
A10: B1.1 | B10: B · Wedge | C10: B1 · PRD del wedge | D10: Delimitar el alcance funcional (Visor + ISO 19650 + CTE) | E10: Lista de funcionalidades del MVP | F10: Producto (PM) | G10: P0 | H10: 2 | I10: M1 | J10: Pendiente | K10: 0
A11: B1.2 | B11: B · Wedge | C11: B1 · PRD del wedge | D11: Definir la frontera con el cálculo (qué queda fuera) | E11: Documento de frontera funcional/legal | F11: Producto (PM) | G11: P0 | H11: 1 | I11: M1 | J11: Pendiente | K11: 0 | L11: B1.1
A12: B1.3 | B12: B · Wedge | C12: B1 · PRD del wedge | D12: Definir buyer persona y propuesta de valor | E12: Perfil de cliente y propuesta de valor | F12: Negocio / Comercial | G12: P1 | H12: 1 | I12: M2 | J12: Pendiente | K12: 0 | L12: B1.1
A13: B1.4 | B13: B · Wedge | C13: B1 · PRD del wedge | D13: Pricing preliminar y modelo de suscripción | E13: Hipótesis de pricing por empresa | F13: Negocio / Comercial | G13: P1 | H13: 1 | I13: M2 | J13: Pendiente | K13: 0 | L13: B1.3
A14: B1.5 | B14: B · Wedge | C14: B1 · PRD del wedge | D14: Redactar y aprobar el PRD | E14: PRD del wedge aprobado (ENTREGABLE DE FASE) | F14: Producto (PM) | G14: P0 | H14: 2 | I14: M3 | J14: Pendiente | K14: 0 | L14: B1.2;B1.3;B1.4
A15: B2.1 | B15: B · Wedge | C15: B2 · Inventario y empaquetado de componentes | D15: Inventariar componentes existentes y su madurez | E15: Matriz componente -> estado de madurez | F15: Ing. BIM / IFC | G15: P0 | H15: 2 | I15: M2 | J15: Pendiente | K15: 0 | L15: B1.1
A16: B2.2 | B16: B · Wedge | C16: B2 · Inventario y empaquetado de componentes | D16: Identificar gaps funcionales del MVP | E16: Lista priorizada de gaps a cubrir | F16: Ing. BIM / IFC | G16: P1 | H16: 2 | I16: M3 | J16: Pendiente | K16: 0 | L16: B2.1
A17: B2.3 | B17: B · Wedge | C17: B2 · Inventario y empaquetado de componentes | D17: Plan de empaquetado como aplicación web | E17: Plan técnico de empaquetado del wedge | F17: Ing. BIM / IFC | G17: P1 | H17: 2 | I17: M4 | J17: Pendiente | K17: 0 | L17: B2.2
A18: B3.1 | B18: B · Wedge | C18: B3 · Pipeline de pilotos | D18: Identificar 3-5 despachos candidatos | E18: Lista cualificada de candidatos | F18: Negocio / Comercial | G18: P0 | H18: 2 | I18: M2 | J18: Pendiente | K18: 0
A19: B3.2 | B19: B · Wedge | C19: B3 · Pipeline de pilotos | D19: Preparar material de pitch / demo | E19: Pitch deck + demo del wedge | F19: Negocio / Comercial | G19: P1 | H19: 2 | I19: M3 | J19: Pendiente | K19: 0 | L19: B1.5;B3.1
A20: B3.3 | B20: B · Wedge | C20: B3 · Pipeline de pilotos | D20: Contactar y cualificar candidatos | E20: Reuniones realizadas y feedback registrado | F20: Negocio / Comercial | G20: P1 | H20: 4 | I20: M4 | J20: Pendiente | K20: 0 | L20: B3.2
A21: B3.4 | B21: B · Wedge | C21: B3 · Pipeline de pilotos | D21: Firmar cartas de intención (LOI) | E21: ≥3 LOIs firmadas (ENTREGABLE DE FASE) | F21: Dirección (JM) | G21: P0 | H21: 3 | I21: M5 | J21: Pendiente | K21: 0 | L21: B3.3
A22: N1.1 | B22: N · Núcleo/Industrialización | C22: N1 · Reproducibilidad (madurez N1) | D22: Consolidar monorepo y control de versiones | E22: Repositorio único versionado y estructurado | F22: Ing. Núcleo / FEM | G22: P0 | H22: 2 | I22: M1 | J22: Pendiente | K22: 0
A23: N1.2 | B23: N · Núcleo/Industrialización | C23: N1 · Reproducibilidad (madurez N1) | D23: Fijar dependencias y build determinista | E23: Lockfiles + build reproducible documentado | F23: Ing. Núcleo / FEM | G23: P0 | H23: 2 | I23: M2 | J23: Pendiente | K23: 0 | L23: N1.1
A24: N1.3 | B24: N · Núcleo/Industrialización | C24: N1 · Reproducibilidad (madurez N1) | D24: Empaquetado firmado de núcleo y plugins | E24: Artefactos versionados y firmados | F24: Ing. Núcleo / FEM | G24: P1 | H24: 2 | I24: M2 | J24: Pendiente | K24: 0 | L24: N1.2
A25: N1.4 | B25: N · Núcleo/Industrialización | C25: N1 · Reproducibilidad (madurez N1) | D25: Documentar la toolchain | E25: Guía de toolchain y entorno reproducible | F25: Ing. Núcleo / FEM | G25: P2 | H25: 1 | I25: M3 | J25: Pendiente | K25: 0 | L25: N1.2
A26: N2.1 | B26: N · Núcleo/Industrialización | C26: N2 · Casos golden y verificación (madurez N2) | D26: Formalizar casos existentes (PUE/LIN/INC) como suite | E26: Suite de casos golden ejecutable | F26: QA / Verificación | G26: P0 | H26: 4 | I26: M3 | J26: Pendiente | K26: 0 | L26: N1.1
A27: N2.2 | B27: N · Núcleo/Industrialización | C27: N2 · Casos golden y verificación (madurez N2) | D27: Definir el oráculo numérico de referencia | E27: Oráculo documentado (referencia de validación) | F27: Ing. Núcleo / FEM | G27: P0 | H27: 2 | I27: M2 | J27: Pendiente | K27: 0
A28: N2.3 | B28: N · Núcleo/Industrialización | C28: N2 · Casos golden y verificación (madurez N2) | D28: Automatizar las puertas espejo/APTO | E28: Comprobación espejo automática reutilizable | F28: QA / Verificación | G28: P0 | H28: 3 | I28: M4 | J28: Pendiente | K28: 0 | L28: N2.1;N2.2
A29: N2.4 | B29: N · Núcleo/Industrialización | C29: N2 · Casos golden y verificación (madurez N2) | D29: Informe de validación numérica (baseline) | E29: Informe de validación (ENTREGABLE DE FASE) | F29: QA / Verificación | G29: P0 | H29: 2 | I29: M5 | J29: Pendiente | K29: 0 | L29: N2.3
A30: N3.1 | B30: N · Núcleo/Industrialización | C30: N3 · Gobierno y métricas de arranque | D30: Definir KPIs de la fase y umbrales del gate | E30: Cuadro de KPIs y criterios de salida | F30: Dirección (JM) | G30: P1 | H30: 1 | I30: M1 | J30: Pendiente | K30: 0
A31: N3.2 | B31: N · Núcleo/Industrialización | C31: N3 · Gobierno y métricas de arranque | D31: Tablero de seguimiento del backlog | E31: Tablero operativo en uso | F31: Producto (PM) | G31: P1 | H31: 1 | I31: M1 | J31: Pendiente | K31: 0 | L31: N3.1
A32: N3.3 | B32: N · Núcleo/Industrialización | C32: N3 · Gobierno y métricas de arranque | D32: Instrumentación básica de coste de inferencia | E32: Medición de coste por proyecto/caso | F32: Ing. Núcleo / FEM | G32: P2 | H32: 2 | I32: M4 | J32: Pendiente | K32: 0 | L32: N1.1

Sheet Épicas
A1: Épica | B1: Track | C1: Objetivo | D1: Entregable principal | E1: Nº tareas | F1: Hechas | G1: % avance
A2: A1 · Operación en proyectos piloto internos | B2: A · Interno | C2: Usar el ecosistema en proyectos reales y capturar criterios. | D2: Proyectos ejecutados + criterios documentados | E2: =COUNTIF(Backlog!$C$2:$C$32,"A1 · Operación en proyectos piloto internos") | F2: =COUNTIFS(Backlog!$C$2:$C$32,"A1 · Operación en proyectos piloto internos",Backlog!$J$2:$J$32,"Hecho") | G2: =IF(E2=0,0,F2/E2)
A3: A2 · Baseline de ROI interno | B3: A · Interno | C3: Medir horas y retrabajo para fijar el baseline. | D3: Memoria de baseline de ROI | E3: =COUNTIF(Backlog!$C$2:$C$32,"A2 · Baseline de ROI interno") | F3: =COUNTIFS(Backlog!$C$2:$C$32,"A2 · Baseline de ROI interno",Backlog!$J$2:$J$32,"Hecho") | G3: =IF(E3=0,0,F3/E3)
A4: B1 · PRD del wedge | B4: B · Wedge | C4: Definir el producto de la capa BIM/cumplimiento. | D4: PRD del wedge aprobado | E4: =COUNTIF(Backlog!$C$2:$C$32,"B1 · PRD del wedge") | F4: =COUNTIFS(Backlog!$C$2:$C$32,"B1 · PRD del wedge",Backlog!$J$2:$J$32,"Hecho") | G4: =IF(E4=0,0,F4/E4)
A5: B2 · Inventario y empaquetado de componentes | B5: B · Wedge | C5: Conocer madurez y gaps del MVP. | D5: Plan de empaquetado del wedge | E5: =COUNTIF(Backlog!$C$2:$C$32,"B2 · Inventario y empaquetado de componentes") | F5: =COUNTIFS(Backlog!$C$2:$C$32,"B2 · Inventario y empaquetado de componentes",Backlog!$J$2:$J$32,"Hecho") | G5: =IF(E5=0,0,F5/E5)
A6: B3 · Pipeline de pilotos | B6: B · Wedge | C6: Conseguir despachos piloto comprometidos. | D6: ≥3 LOIs firmadas | E6: =COUNTIF(Backlog!$C$2:$C$32,"B3 · Pipeline de pilotos") | F6: =COUNTIFS(Backlog!$C$2:$C$32,"B3 · Pipeline de pilotos",Backlog!$J$2:$J$32,"Hecho") | G6: =IF(E6=0,0,F6/E6)
A7: N1 · Reproducibilidad (madurez N1) | B7: N · Núcleo/Industrialización | C7: Llevar el núcleo a build reproducible y versionado. | D7: Núcleo reproducible y empaquetado | E7: =COUNTIF(Backlog!$C$2:$C$32,"N1 · Reproducibilidad (madurez N1)") | F7: =COUNTIFS(Backlog!$C$2:$C$32,"N1 · Reproducibilidad (madurez N1)",Backlog!$J$2:$J$32,"Hecho") | G7: =IF(E7=0,0,F7/E7)
A8: N2 · Casos golden y verificación (madurez N2) | B8: N · Núcleo/Industrialización | C8: Crear la red de seguridad de calidad del núcleo. | D8: Suite golden + informe de validación | E8: =COUNTIF(Backlog!$C$2:$C$32,"N2 · Casos golden y verificación (madurez N2)") | F8: =COUNTIFS(Backlog!$C$2:$C$32,"N2 · Casos golden y verificación (madurez N2)",Backlog!$J$2:$J$32,"Hecho") | G8: =IF(E8=0,0,F8/E8)
A9: N3 · Gobierno y métricas de arranque | B9: N · Núcleo/Industrialización | C9: Instrumentar el seguimiento y los KPIs del gate. | D9: Tablero + cuadro de KPIs | E9: =COUNTIF(Backlog!$C$2:$C$32,"N3 · Gobierno y métricas de arranque") | F9: =COUNTIFS(Backlog!$C$2:$C$32,"N3 · Gobierno y métricas de arranque",Backlog!$J$2:$J$32,"Hecho") | G9: =IF(E9=0,0,F9/E9)

Sheet Roles
A1: Rol | B1: Responsabilidad en Fase 0 | C1: Nombre (rellenar)
A2: Dirección (JM) | B2: Decisiones estratégicas, aprobación de gates, prioridades.
A3: Ing. Núcleo / FEM | B3: Reproducibilidad, casos golden, oráculo numérico, puertas espejo.
A4: Ing. BIM / IFC | B4: Componentes del wedge (Visor, parser/validador IFC, ISO 19650).
A5: Producto (PM) | B5: PRD del wedge, alcance, frontera funcional, métricas.
A6: Negocio / Comercial | B6: Pipeline de pilotos, LOIs, pricing, propuesta de valor.
A7: QA / Verificación | B7: Suite de regresión, validación numérica, informe de QA.
